[2024-08-30T15:39:57.357+0000] {taskinstance.py:1979} INFO - Dependencies all met for dep_context=non-requeueable deps ti=<TaskInstance: spark_retail_analysis_dag.spark_retail_analysis_task manual__2024-08-30T15:34:50.927552+00:00 [queued]>
[2024-08-30T15:39:57.377+0000] {taskinstance.py:1979} INFO - Dependencies all met for dep_context=requeueable deps ti=<TaskInstance: spark_retail_analysis_dag.spark_retail_analysis_task manual__2024-08-30T15:34:50.927552+00:00 [queued]>
[2024-08-30T15:39:57.378+0000] {taskinstance.py:2193} INFO - Starting attempt 2 of 2
[2024-08-30T15:39:57.418+0000] {taskinstance.py:2214} INFO - Executing <Task(SparkSubmitOperator): spark_retail_analysis_task> on 2024-08-30 15:34:50.927552+00:00
[2024-08-30T15:39:57.453+0000] {standard_task_runner.py:60} INFO - Started process 5854 to run task
[2024-08-30T15:39:57.459+0000] {standard_task_runner.py:87} INFO - Running: ['airflow', 'tasks', 'run', 'spark_retail_analysis_dag', 'spark_retail_analysis_task', 'manual__2024-08-30T15:34:50.927552+00:00', '--job-id', '26', '--raw', '--subdir', 'DAGS_FOLDER/spark_retail_analysis_dag.py', '--cfg-path', '/tmp/tmplpnqop0i']
[2024-08-30T15:39:57.468+0000] {standard_task_runner.py:88} INFO - Job 26: Subtask spark_retail_analysis_task
[2024-08-30T15:39:57.581+0000] {logging_mixin.py:188} WARNING - /home/airflow/.local/lib/python3.9/site-packages/airflow/settings.py:194 DeprecationWarning: The sql_alchemy_conn option in [core] has been moved to the sql_alchemy_conn option in [database] - the old setting has been used, but please update your config.
[2024-08-30T15:39:57.857+0000] {task_command.py:423} INFO - Running <TaskInstance: spark_retail_analysis_dag.spark_retail_analysis_task manual__2024-08-30T15:34:50.927552+00:00 [running]> on host dataeng-airflow-scheduler
[2024-08-30T15:39:58.324+0000] {taskinstance.py:2510} INFO - Exporting env vars: AIRFLOW_CTX_DAG_OWNER='airflow' AIRFLOW_CTX_DAG_ID='spark_retail_analysis_dag' AIRFLOW_CTX_TASK_ID='spark_retail_analysis_task' AIRFLOW_CTX_EXECUTION_DATE='2024-08-30T15:34:50.927552+00:00' AIRFLOW_CTX_TRY_NUMBER='2' AIRFLOW_CTX_DAG_RUN_ID='manual__2024-08-30T15:34:50.927552+00:00'
[2024-08-30T15:39:58.381+0000] {base.py:83} INFO - Using connection ID 'spark_default' for task execution.
[2024-08-30T15:39:58.384+0000] {spark_submit.py:403} INFO - Spark-Submit cmd: spark-submit --master yarn --conf spark.executor.memory=2g --conf spark.driver.memory=1g --conf spark.dynamicAllocation.enabled=false --conf spark.shuffle.service.enabled=false --conf spark.yarn.appMasterEnv.JAVA_HOME=/usr/lib/jvm/java-11-openjdk-amd64 --conf spark.yarn.appMasterEnv.PYSPARK_PYTHON=/usr/bin/python3 --conf spark.yarn.appMasterEnv.SPARK_HOME=/path/to/spark --name arrow-spark --queue root.default /opt/airflow/scripts/spark-retail-analysis.py
[2024-08-30T15:39:58.500+0000] {spark_submit.py:579} INFO - /home/airflow/.local/bin/spark-submit: line 27: /path/to/spark/bin/spark-class: No such file or directory
[2024-08-30T15:39:58.528+0000] {taskinstance.py:2728} ERROR - Task failed with exception
Traceback (most recent call last):
  File "/home/airflow/.local/lib/python3.9/site-packages/airflow/models/taskinstance.py", line 444, in _execute_task
    result = _execute_callable(context=context, **execute_callable_kwargs)
  File "/home/airflow/.local/lib/python3.9/site-packages/airflow/models/taskinstance.py", line 414, in _execute_callable
    return execute_callable(context=context, **execute_callable_kwargs)
  File "/home/airflow/.local/lib/python3.9/site-packages/airflow/providers/apache/spark/operators/spark_submit.py", line 174, in execute
    self._hook.submit(self.application)
  File "/home/airflow/.local/lib/python3.9/site-packages/airflow/providers/apache/spark/hooks/spark_submit.py", line 505, in submit
    raise AirflowException(
airflow.exceptions.AirflowException: Cannot execute: spark-submit --master yarn --conf spark.executor.memory=2g --conf spark.driver.memory=1g --conf spark.dynamicAllocation.enabled=false --conf spark.shuffle.service.enabled=false --conf spark.yarn.appMasterEnv.JAVA_HOME=/usr/lib/jvm/java-11-openjdk-amd64 --conf spark.yarn.appMasterEnv.PYSPARK_PYTHON=/usr/bin/python3 --conf spark.yarn.appMasterEnv.SPARK_HOME=/path/to/spark --name arrow-spark --queue root.default /opt/airflow/scripts/spark-retail-analysis.py. Error code is: 127.
[2024-08-30T15:39:58.537+0000] {taskinstance.py:1149} INFO - Marking task as FAILED. dag_id=spark_retail_analysis_dag, task_id=spark_retail_analysis_task, execution_date=20240830T153450, start_date=20240830T153957, end_date=20240830T153958
[2024-08-30T15:39:58.573+0000] {logging_mixin.py:188} WARNING - /home/airflow/.local/lib/python3.9/site-packages/airflow/utils/email.py:154 RemovedInAirflow3Warning: Fetching SMTP credentials from configuration variables will be deprecated in a future release. Please set credentials using a connection instead.
[2024-08-30T15:39:58.576+0000] {configuration.py:1046} WARNING - section/key [smtp/smtp_user] not found in config
[2024-08-30T15:39:58.577+0000] {email.py:270} INFO - Email alerting: attempt 1
[2024-08-30T15:39:58.587+0000] {taskinstance.py:1127} ERROR - Error when executing <lambda> callback
Traceback (most recent call last):
  File "/home/airflow/.local/lib/python3.9/site-packages/airflow/models/taskinstance.py", line 2357, in _run_raw_task
    self._execute_task_with_callbacks(context, test_mode, session=session)
  File "/home/airflow/.local/lib/python3.9/site-packages/airflow/models/taskinstance.py", line 2529, in _execute_task_with_callbacks
    result = self._execute_task(context, task_orig)
  File "/home/airflow/.local/lib/python3.9/site-packages/airflow/models/taskinstance.py", line 2546, in _execute_task
    return _execute_task(self, context, task_orig)
  File "/home/airflow/.local/lib/python3.9/site-packages/airflow/models/taskinstance.py", line 444, in _execute_task
    result = _execute_callable(context=context, **execute_callable_kwargs)
  File "/home/airflow/.local/lib/python3.9/site-packages/airflow/models/taskinstance.py", line 414, in _execute_callable
    return execute_callable(context=context, **execute_callable_kwargs)
  File "/home/airflow/.local/lib/python3.9/site-packages/airflow/providers/apache/spark/operators/spark_submit.py", line 174, in execute
    self._hook.submit(self.application)
  File "/home/airflow/.local/lib/python3.9/site-packages/airflow/providers/apache/spark/hooks/spark_submit.py", line 505, in submit
    raise AirflowException(
airflow.exceptions.AirflowException: Cannot execute: spark-submit --master yarn --conf spark.executor.memory=2g --conf spark.driver.memory=1g --conf spark.dynamicAllocation.enabled=false --conf spark.shuffle.service.enabled=false --conf spark.yarn.appMasterEnv.JAVA_HOME=/usr/lib/jvm/java-11-openjdk-amd64 --conf spark.yarn.appMasterEnv.PYSPARK_PYTHON=/usr/bin/python3 --conf spark.yarn.appMasterEnv.SPARK_HOME=/path/to/spark --name arrow-spark --queue root.default /opt/airflow/scripts/spark-retail-analysis.py. Error code is: 127.

During handling of the above exception, another exception occurred:

Traceback (most recent call last):
  File "/home/airflow/.local/lib/python3.9/site-packages/airflow/models/taskinstance.py", line 1124, in _run_finished_callback
    callback(context)
  File "/opt/airflow/dags/spark_retail_analysis_dag.py", line 15, in <lambda>
    'on_failure_callback': lambda context: send_email(
  File "/home/airflow/.local/lib/python3.9/site-packages/airflow/utils/email.py", line 80, in send_email
    return backend(
  File "/home/airflow/.local/lib/python3.9/site-packages/airflow/utils/email.py", line 154, in send_email_smtp
    send_mime_email(e_from=mail_from, e_to=recipients, mime_msg=msg, conn_id=conn_id, dryrun=dryrun)
  File "/home/airflow/.local/lib/python3.9/site-packages/airflow/utils/email.py", line 272, in send_mime_email
    smtp_conn = _get_smtp_connection(smtp_host, smtp_port, smtp_timeout, smtp_ssl)
  File "/home/airflow/.local/lib/python3.9/site-packages/airflow/utils/email.py", line 316, in _get_smtp_connection
    return smtplib.SMTP(host=host, port=port, timeout=timeout)
  File "/usr/local/lib/python3.9/smtplib.py", line 255, in __init__
    (code, msg) = self.connect(host, port)
  File "/usr/local/lib/python3.9/smtplib.py", line 341, in connect
    self.sock = self._get_socket(host, port, self.timeout)
  File "/usr/local/lib/python3.9/smtplib.py", line 312, in _get_socket
    return socket.create_connection((host, port), timeout,
  File "/usr/local/lib/python3.9/socket.py", line 844, in create_connection
    raise err
  File "/usr/local/lib/python3.9/socket.py", line 832, in create_connection
    sock.connect(sa)
ConnectionRefusedError: [Errno 111] Connection refused
[2024-08-30T15:39:58.632+0000] {standard_task_runner.py:107} ERROR - Failed to execute job 26 for task spark_retail_analysis_task (Cannot execute: spark-submit --master yarn --conf spark.executor.memory=2g --conf spark.driver.memory=1g --conf spark.dynamicAllocation.enabled=false --conf spark.shuffle.service.enabled=false --conf spark.yarn.appMasterEnv.JAVA_HOME=/usr/lib/jvm/java-11-openjdk-amd64 --conf spark.yarn.appMasterEnv.PYSPARK_PYTHON=/usr/bin/python3 --conf spark.yarn.appMasterEnv.SPARK_HOME=/path/to/spark --name arrow-spark --queue root.default /opt/airflow/scripts/spark-retail-analysis.py. Error code is: 127.; 5854)
[2024-08-30T15:39:58.659+0000] {local_task_job_runner.py:234} INFO - Task exited with return code 1
[2024-08-30T15:39:58.685+0000] {taskinstance.py:3309} INFO - 0 downstream tasks scheduled from follow-on schedule check
